[0m11:53:08.358600 [debug] [MainThread]: Sending event: {'category': 'dbt', 'action': 'invocation', 'label': 'start', 'context': [<snowplow_tracker.self_describing_json.SelfDescribingJson object at 0x7e0b1522ca70>, <snowplow_tracker.self_describing_json.SelfDescribingJson object at 0x7e0b13e6c290>, <snowplow_tracker.self_describing_json.SelfDescribingJson object at 0x7e0b1461fec0>]}


============================== 11:53:08.399733 | a59d99dd-9371-4c2f-a48d-281be2567067 ==============================
[0m11:53:08.399733 [info ] [MainThread]: Running with dbt=1.10.4
[0m11:53:08.403166 [debug] [MainThread]: running dbt with arguments {'printer_width': '80', 'indirect_selection': 'eager', 'write_json': 'True', 'log_cache_events': 'False', 'partial_parse': 'True', 'cache_selected_only': 'False', 'profiles_dir': '/home/apple_shay/.dbt', 'debug': 'False', 'warn_error': 'None', 'log_path': 'logs', 'version_check': 'True', 'fail_fast': 'False', 'use_colors': 'True', 'use_experimental_parser': 'False', 'no_print': 'None', 'quiet': 'False', 'empty': 'False', 'warn_error_options': 'WarnErrorOptionsV2(error=[], warn=[], silence=[])', 'invocation_command': 'dbt run', 'static_parser': 'True', 'introspect': 'True', 'target_path': 'None', 'log_format': 'default', 'send_anonymous_usage_stats': 'True'}
[0m11:53:08.458872 [error] [MainThread]: Encountered an error:
Runtime Error
  No dbt_project.yml found at expected path /mnt/b/de/ETL1/etl_pipeline_project/dbt_project.yml
  Verify that each entry within packages.yml (and their transitive dependencies) contains a file named dbt_project.yml
  
[0m11:53:08.465589 [debug] [MainThread]: Resource report: {"command_name": "run", "command_success": false, "command_wall_clock_time": 0.18228535, "process_in_blocks": "16160", "process_kernel_time": 1.300845, "process_mem_max_rss": "97836", "process_out_blocks": "0", "process_user_time": 2.0264}
[0m11:53:08.467314 [debug] [MainThread]: Command `dbt run` failed at 11:53:08.467127 after 0.18 seconds
[0m11:53:08.470382 [debug] [MainThread]: Sending event: {'category': 'dbt', 'action': 'invocation', 'label': 'end', 'context': [<snowplow_tracker.self_describing_json.SelfDescribingJson object at 0x7e0b1522ca70>, <snowplow_tracker.self_describing_json.SelfDescribingJson object at 0x7e0b1448a480>, <snowplow_tracker.self_describing_json.SelfDescribingJson object at 0x7e0b13e44b00>]}
[0m11:53:08.472814 [debug] [MainThread]: Flushing usage events
[0m11:53:09.225457 [debug] [MainThread]: An error was encountered while trying to flush usage events
[0m11:53:31.388489 [debug] [MainThread]: Sending event: {'category': 'dbt', 'action': 'invocation', 'label': 'start', 'context': [<snowplow_tracker.self_describing_json.SelfDescribingJson object at 0x70ec781cfb00>, <snowplow_tracker.self_describing_json.SelfDescribingJson object at 0x70ec791c5550>, <snowplow_tracker.self_describing_json.SelfDescribingJson object at 0x70ec7814e3f0>]}


============================== 11:53:31.408612 | bf6bdcbc-1532-4bd5-a857-852e5c96553f ==============================
[0m11:53:31.408612 [info ] [MainThread]: Running with dbt=1.10.4
[0m11:53:31.410470 [debug] [MainThread]: running dbt with arguments {'printer_width': '80', 'indirect_selection': 'eager', 'log_cache_events': 'False', 'write_json': 'True', 'partial_parse': 'True', 'cache_selected_only': 'False', 'profiles_dir': '/home/apple_shay/.dbt', 'debug': 'False', 'version_check': 'True', 'log_path': 'logs', 'warn_error': 'None', 'fail_fast': 'False', 'use_colors': 'True', 'use_experimental_parser': 'False', 'no_print': 'None', 'quiet': 'False', 'empty': 'None', 'warn_error_options': 'WarnErrorOptionsV2(error=[], warn=[], silence=[])', 'static_parser': 'True', 'invocation_command': 'dbt test', 'log_format': 'default', 'target_path': 'None', 'introspect': 'True', 'send_anonymous_usage_stats': 'True'}
[0m11:53:31.413161 [error] [MainThread]: Encountered an error:
Runtime Error
  No dbt_project.yml found at expected path /mnt/b/de/ETL1/etl_pipeline_project/dbt_project.yml
  Verify that each entry within packages.yml (and their transitive dependencies) contains a file named dbt_project.yml
  
[0m11:53:31.418411 [debug] [MainThread]: Resource report: {"command_name": "test", "command_success": false, "command_wall_clock_time": 0.10169446, "process_in_blocks": "8456", "process_kernel_time": 1.34408, "process_mem_max_rss": "97852", "process_out_blocks": "0", "process_user_time": 1.977349}
[0m11:53:31.421128 [debug] [MainThread]: Command `dbt test` failed at 11:53:31.420909 after 0.10 seconds
[0m11:53:31.423546 [debug] [MainThread]: Sending event: {'category': 'dbt', 'action': 'invocation', 'label': 'end', 'context': [<snowplow_tracker.self_describing_json.SelfDescribingJson object at 0x70ec77e999a0>, <snowplow_tracker.self_describing_json.SelfDescribingJson object at 0x70ec78591670>, <snowplow_tracker.self_describing_json.SelfDescribingJson object at 0x70ec779dfd70>]}
[0m11:53:31.426367 [debug] [MainThread]: Flushing usage events
[0m11:53:32.164457 [debug] [MainThread]: An error was encountered while trying to flush usage events
